Workbook
Name Segment: #REF!
Name Segment: #REF!
Name Segment: #REF!
Name Segment: #REF!

Sheet COVER SHEET
A1: RSB WORKBOOK
A2: CUSTOMER NAME | B2: LUMOS | E2: ENGINEER | F2: CHAD ROBERTSON
A3: CUSTOMER LOCATION | B3: VIRGINIA | E3: DATE
A4: MARKET | B4: CHESTERFIELD | E4: Project # | F4: CHST
C5: Permits Due Date
A6: CAPITAL BUDGET # | B6: =IF(ISBLANK(F4), "", F4) | C6: Planning Guide #
F7: Cost | G7: Days
A8: Project # | B8: =IF(ISBLANK(F4), "", F4) | C8: Total Aerial (Eng-Aerial Footage) | D8: =D9+D10 | E8: DOT | F8: =LABOR!F49
C9: New Aerial Fiber Cable Placement | D9: =SUM(LABOR!B162:B170,LABOR!B200) | E9: Municipal | F9: =LABOR!F50
C10: Total Overlash | D10: =SUM(LABOR!B176,LABOR!B201,LABOR!B205,LABOR!B206) | E10: RR | F10: =LABOR!F51
A11: Planned Completion | C11: Total Underground (Eng-New Conduit Footage) | D11: =SUM('LABOR SPAN SHEET'!AD2) | E11: Easement | F11: =TOTALS!C27
A12: HLE | C12: Total Existing Conduit Footage | D12: ='LABOR SPAN SHEET'!AA2 | E12: Pole | F12: =LABOR!F52
A13: Detailed | C13: Total Fiber (Eng-Fiber Footage) | D13: =SUM(MATERIAL!B31:B37,MATERIAL!B107:B113,MATERIAL!B175:B181) | E13: Conduit | F13: =LABOR!F53
A14: Job Package | C14: Total Fiber & Conduit (Eng-Total Bld Footage | D14: =D8+D11+D12 | E14: Other | F14: 10000
C15: Variance Approved Dates | E15: Traffic Control | F15: =TOTALS!C30
C16: HLE to Detailed Est | E16: Engineering | F16: =SUM(TOTALS!C9:C12)
A17: Total OSP Cost (- Eng Vendor Cost) | B17: =TOTALS!C71-F16 | C17: Detailed Est to JP | E17: Drafting | F17: =SUM(TOTALS!C14:C15)
A18: Total Including Equ. | B18: =B17+F21 | E18: Permitting | F18: =SUM(TOTALS!C17:C28)
E19: Construction | F19: =SUM(TOTALS!C32,TOTALS!C35,TOTALS!C37,TOTALS!C40:C41,TOTALS!C44:C45,TOTALS!C48,TOTALS!C52,TOTALS!C64,TOTALS!C66)
A20: ON NET | B20: QTY | C20: NEAR NET | D20: QTY | E20: Splicing | F20: =SUM(TOTALS!C54,TOTALS!C57,TOTALS!C59,TOTALS!C62)
A21: SFU Residential-ON | B21: =COUNTIFS('House Count'!F:F, "RES-HOA",'House Count'!H:H,"Y")+COUNTIFS('House Count'!F:F, "RES-SFU",'House Count'!H:H,"Y") | C21: SFU Residential-NN | D21: =COUNTIFS('House Count'!F:F, "RES-HOA",'House Count'!H:H,"N")+COUNTIFS('House Count'!F:F, "RES-SFU",'House Count'!H:H,"N") | E21: Access Equipment | F21: =TOTALS!C67
A22: MDU Residential-ON | B22: =COUNTIFS('House Count'!F:F, "RES-MDU",'House Count'!H:H,"Y") | C22: MDU Residential-NN | D22: =COUNTIFS('House Count'!F:F, "RES-MDU",'House Count'!H:H,"N") | E22: LCP Equipment | F22: =MATERIAL!H340
A23: Business-ON | B23: =COUNTIFS('House Count'!F:F, "COMM-SU",'House Count'!H:H,"Y")+COUNTIFS('House Count'!F:F, "COM-MTU",'House Count'!H:H,"Y") | C23: Business-NN | D23: =COUNTIFS('House Count'!F:F, "COMM-SU",'House Count'!H:H,"N")+COUNTIFS('House Count'!F:F, "COM-MTU",'House Count'!H:H,"N")
A24: Vacant Lots-ON | B24: =COUNTIFS('House Count'!F:F, "VL",'House Count'!H:H,"Y") | C24: Vacant Lots-NN | D24: =COUNTIFS('House Count'!F:F, "VL",'House Count'!H:H,"N")
A25: TOTAL ON NET: | B25: =SUM(B21:B24) | C25: TOTAL NEAR NET: | D25: =SUM(D21:D24)
A27: LIST OF PERMITS - EASEMENTS - IRU SPLICING NEEDED
A28: NAME | B28: DESCRIPTION | E28: DUE | F28: SENT | G28: APPROVED
A38: COMMENTS
A45: *** BELOW IS FOR ADMIN USE ONLY***
A46: JP Approval Date: | C46: Approved By: | E46: Date sent to Construction:
A47: Construction Complete: | D47: Miss Utility Polygon:
A48: REVISION DATE 11/18/2025

Sheet MAP
A1: PASTE LOCATION MAP HERE

Sheet MATERIAL
A1: CUSTOMER NAME | C1: ='COVER SHEET'!B2 | G1: Tax | H1: 0.05
A2: ENGINEER | C2: ='COVER SHEET'!F2 | G2: Provisioning | H2: 0.1
A3: Project # | C3: =IF(ISBLANK('COVER SHEET'!F4),"",'COVER SHEET'!F4)
A4: Task Name | B4: QUANTITY | C4: ACTUAL QUANITY | D4: REEL NUMBER | E4: ITEM # | F4: DESCRIPTION | G4: COST | H4: TOTAL
F5: POLE MATERIAL
A6: O.POLES | E6: POLE30C3 | F6: Pole 30' CL3 | G6: 265.72 | H6: =B6*G6
A7: O.POLES | E7: POLE30C4 | F7: Pole 30 CL4 | G7: 221.98 | H7: =G7*B7
A8: O.POLES | E8: POLE30C5 | F8: Pole 30 CL5 | G8: 195.39 | H8: =B8*G8
A9: O.POLES | E9: POLE35C4 | F9: Pole 35 CL4 | G9: 280.86 | H9: =B9*G9
A10: O.POLES | E10: POLE35C5 | F10: Pole 35 CL5 | G10: 235.85 | H10: =B10*G10
A11: O.POLES | E11: POLE40C2 | F11: Pole 40' CL2 | G11: 395 | H11: =B11*G11
A12: O.POLES | E12: POLE40C3 | F12: Pole 40 CL3 | G12: 381.29 | H12: =B12*G12
A13: O.POLES | E13: POLE40C4 | F13: Pole 40' CL4 | G13: 325.97 | H13: =B13*G13
A14: O.POLES | E14: POLE40C5 | F14: Pole 40' CL5 | G14: 274.22 | H14: =B14*G14
A15: O.POLES | E15: POLE45C1 | F15: Pole 45' CL1 Not stocked item, Contact Purchasing for Price/Availability | H15: =B15*G15
A16: O.POLES | E16: POLE45C2 | F16: Pole 45' CL2 Not stocked item, Contact Purchasing for Price/Availability | H16: =B16*G16
A17: O.POLES | E17: POLE45C3 | F17: Pole 45' CL3 | G17: 480.52 | H17: =B17*G17
A18: O.POLES | E18: POLE45C4 | F18: Pole 45' CL4 | G18: 325.97 | H18: =B18*G18
A19: O.POLES | E19: POLE50C2 | F19: Pole 50' CL2 | G19: 624.08 | H19: =B19*G19
A20: O.POLES | E20: POLE55C1 | F20: Pole 55' CL1 Not stocked item, Contact Purchasing for Price/Availability | H20: =B20*G20
A21: O.POLES | E21: POLE55C2 | F21: Pole 55' CL2 | G21: 733.14 | H21: =B21*G21
A22: MISC. | H22: =B22*G22
A23: MISC. | H23: =B23*G23
A24: MISC. | H24: =B24*G24
A25: MISC. | H25: =B25*G25
F26: SUB-TOTAL - O.POLES | H26: =SUM(H6:H25)
F27: PROVISIONING - POLE MATERIAL | H27: =H26*(H1+H2)
F28: TOTAL - O.POLES | H28: =H27+H26
A29: <----Click the + to Expand or Collapse the "POLE MATERIAL" Section
B30: - | F30: AERIAL FIBER ASSET MATERIAL
A31: O.FBR.AERL | E31: FIBCOMFIG8 | F31: FIBER - COMMSCOPE FIGURE 8 M-006-MN-8W-F06NS/25G/109 (RDF) | H31: =B31*G31
A32: O.FBR.AERL | B32: ='CABLE SHEET'!I3 | E32: FIBGEN48ARMR | F32: 048 Loose Tube PN D-048-LA-8W-F12NS; 048ZUC-T4122D20; AT3CEH2YT-048 | G32: 0.31 | H32: =B32*G32
A33: O.FBR.AERL | B33: ='CABLE SHEET'!I4 | E33: FIBGEN96ARMR | F33: 096 Loose Tube PN D-096-LA-8W-F12NS; 096ZUC-T4122D20; AT3CEH2YT-096 | G33: 0.62 | H33: =B33*G33
A34: O.FBR.AERL | B34: ='CABLE SHEET'!I5 | E34: FIBGEN144RIB | F34: 144 Ribbon FIber PN 144EC5-14100D53 | G34: 0.98 | H34: =B34*G34
A35: O.FBR.AERL | E35: FIBOFS192LTARMR | F35: FIBER OFS AT3CEH2YT-192-FORTEX NON-DIELECTRIC LIGHT ARMOR | H35: =B35*G35
A36: O.FBR.AERL | B36: ='CABLE SHEET'!I6 | E36: FIBGEN288RIB | F36: 288 Ribbon FIber PN 288EV5-14100D53 | G36: 1.55 | H36: =B36*G36
A37: O.FBR.AERL | B37: ='CABLE SHEET'!I7 | E37: FIBGEN432RIB | F37: 432 Ribbon Fiber OFS AT-3CE84SX-432; COR 432EV5-14100D53; STL RA0432FSN06TFBUUS | G37: 3.6 | H37: =B37*G37
F38: AERIAL CABLE ASSET MATERIAL
A39: O.FBR.AERL | E39: CBLFS2522 | F39: CABLE F.S. 25-22 | H39: =B39*G39
A40: O.FBR.AERL | E40: CBLFSKIN10024 | F40: CABLE FOAM SKIN 100-24 | H40: =B40*G40
...

Sheet LABOR
A1: CUSTOMER NAME | C1: - | D1: ='COVER SHEET'!B2 | E1: Solid Rock Adder
A2: ENGINEER | C2: - | D2: ='COVER SHEET'!F2
A3: Project # | C3: - | D3: ='COVER SHEET'!F4
A5: Task Name | B5: QUANTITY | C5: UNIT | D5: UNIT DESCRIPTION | E5: UNIT COST | F5: TOTAL
B6: =IF(SUM(F29)>0,"-","") | D6: ENGINEERING
D7: PROJECT PLANNING / DESIGN - COMPANY LABOR | E7: 0.7 | F7: =E7*B7
D8: PROJECT PLANNING / DESIGN - CONTRACT LABOR | E8: 50 | F8: =E8*B8
D9: CONTRACTOR MINIMUM AERIAL/BURIED/UNDERGROUND CHARGE | E9: 1 | F9: =E9*B9
D10: CONTRACTOR - FLAT RATE - AERIAL - PER LINEAR FOOT 0-1 MILE | E10: 0.5 | F10: =E10*B10
D11: CONTRACTOR - FLAT RATE - AERIAL - PER LINEAR FOOT 1-2 MILE | E11: 0.5 | F11: =E11*B11
D12: CONTRACTOR - FLAT RATE - AERIAL - PER LINEAR FOOT 2-5 MILE | E12: 0.5 | F12: =E12*B12
D13: CONTRACTOR - FLAT RATE - BURIED/UNDERGROUND - PER LINEAR FOOT 0-1 MILE | E13: 0.5 | F13: =E13*B13
D14: CONTRACTOR - FLAT RATE - BURIED/UNDERGROUND - PER LINEAR FOOT 1-2 MILE | E14: 0.5 | F14: =E14*B14
B15: =SUM('LABOR SPAN SHEET'!AD2) | D15: CONTRACTOR - FLAT RATE - BURIED/UNDERGROUND - PER LINEAR FOOT 2-5 MILE | E15: 0.5 | F15: =E15*B15
D16: CONTRACTOR - DESIGN OVER 5 MILES - PER BID | F16: =E16*B16
D17: CONTRACTOR - MAJOR REDESIGN COST - PER FOOT | E17: 0.6 | F17: =E17*B17
D18: CONTRACTOR - PE STAMP - PLUS 15% OF COST | F18: =E18*B18
D19: CONTRACTOR - OSP OFFICE ESTIMATE | E19: 150 | F19: =E19*B19
D20: CONTRACTOR - OSP DETAILED FIELD ESTIMATE | E20: 350 | F20: =E20*B20
D21: CONTRACTOR - CAP RING - SHORT HAUL - LONG HAUL - FIELD ESTIMATE | E21: 500 | F21: =E21*B21
D22: CONTRACTOR - PROJECT MANAGEMENT | E22: 48 | F22: =E22*B22
D23: CONTRACTOR - OSP ENGINEER | E23: 48 | F23: =E23*B23
D24: CONTRACTOR - ASSOCIATE ENGINEER | E24: 37 | F24: =E24*B24
D25: CONTRACTOR - ENGINEER ASSISTANT | E25: 21 | F25: =E25*B25
D26: CONTRACTOR - ENGINEERING ADMIN | E26: 29 | F26: =E26*B26
D27: CONTRACTOR - ENGINEERING ADMIN ASSISTANT | E27: 21 | F27: =E27*B27
D28: LUMOS LABOR - JOB COORDINATION - PROJECT MANAGEMENT | E28: 500 | F28: =E28*B28
D29: TOTAL - ENGINEERING | F29: =SUM(F7:F28)
A30: <----Click the + to Expand or Collapse the "ENGINEERING" Section
B31: =IF(SUM(F35)>0,"-","") | D31: DRAFTING
D32: CONTRACTOR - CAD INPUT / MAPPING (M4) | E32: 32 | F32: =E32*B32
D33: COMPANY LABOR - CAD INPUT/ MAPPING (M4) | F33: =E33*B33
D34: CONTRACTOR - M4 - POSTING TIME | E34: 150 | F34: =E34*B34
D35: TOTAL - DRAFTING | F35: =SUM(F32:F34)
A36: <----Click the + to Expand or Collapse the "DRAFTING" Section
B37: =IF(SUM(F56)>0,"-","") | D37: PERMITTING
D38: EASEMENTS / ACQUISITION - COMPANY LABOR | E38: 50 | F38: =E38*B38
D39: EASEMENTS / ACQUISITION - CONTRACT LABOR | E39: 50 | F39: =E39*B39
D40: CONTRACTOR - NEGOTIATION OF EASEMENT BEYOND FIRST ATTEMPT | E40: 500 | F40: =E40*B40
D41: CONTRACTOR - NEGOTIATION OF BUILDING LICENSE AGREEMENTS | E41: 500 | F41: =E41*B41
...

Sheet TOTALS
A1: NAME | B1: ='COVER SHEET'!B2:D2
A2: LOCATION | B2: ='COVER SHEET'!B3:D3
A3: Project # | B3: ='COVER SHEET'!F4
A4: MetaSolv # | B4: ='COVER SHEET'!B9
A5: DDID # | B5: =RIGHT(B3,5)
A6: CODE | B6: DESCRIPTION | C6: AMOUNT
B7: ENGINEERING
B8: PROJECT PLANNING / DESIGN
B9: Project Planning / Design - Contract Labor | C9: =SUM(LABOR!F8:F27)
B10: Project Planning / Design - Company Labor | C10: =LABOR!F7
B11: Misc. Copper Splicing Labor | C11: =LABOR!F385
B12: Job Coordination/Lumos Labor | C12: =LABOR!F28
B13: JOB PRINTS / DRAFTING
B14: Job Prints / Mapping - Contract Labor | C14: =SUM(LABOR!F32,LABOR!F34)
B15: Job Prints/ Mapping - Company Labor | C15: =LABOR!F33
B16: PERMITS AND AUTHORIZATION
B17: Permits / Authorization - Contract Labor | C17: =LABOR!F44
B18: Permits / Authorization - Company Labor | C18: =LABOR!F43
B19: Easements / Acquisition - Contract Labor | C19: =LABOR!F39
B20: Easements / Acquisition - Company Labor | C20: =LABOR!F38
B21: CONTRACTOR - NEGOTIATION OF EASEMENT BEYOND FIRST ATTEMPT | C21: =LABOR!F40
B22: CONTRACTOR - NEGOTIATION OF BUILDING LICENSE AGREEMENTS | C22: =LABOR!F41
B23: CONTRACTOR - SPECIALIZED PERMITS | C23: =LABOR!F47
B24: CONTRACTOR - PE STAMP - PLUS 15% OF COST | C24: =LABOR!F48
B25: Administration Permitting Time - Company Labor | C25: =LABOR!F45
B26: Administration Permitting Time - Contract Labor | C26: =LABOR!F46
B27: Easement Fees | C27: =LABOR!F42
B28: Permit Fees | C28: =SUM(LABOR!F49:F54)
B29: PROJECT PLANNING / CONSTRUCTION / ADMIN
B30: TRAFFIC CONTROL | C30: =PERMITS!P88
B31: PLACE POLE
A32: O.POLES | B32: Contractor Labor | C32: =SUM(LABOR!F139,LABOR!F159)
A33: O.POLES | B33: Material - Pole | C33: =MATERIAL!H26
A34: O.POLES | B34: Provisioning - Pole Material | C34: =MATERIAL!H27
A35: O.POLES | B35: Total + Tax - Pole Material | C35: =MATERIAL!H28
B36: PLACE CABLE
A37: O.FBR.AERL | B37: Contractor Labor - Aerial Fiber | C37: =SUM(LABOR!F185,LABOR!F216)
A38: O.FBR.AERL | B38: Material - Aerial Fiber | C38: =MATERIAL!H102
A39: O.FBR.AERL | B39: Provisioning - Aerial Material | C39: =MATERIAL!H103
A40: O.FBR.AERL | B40: Total + Tax - Aerial Material | C40: =MATERIAL!H104
...

Sheet CABLE SHEET
B1: Method | C1: New Conduit | G1: Method | H1: Aerial | L1: Method | M1: Existing Conduit
B2: Cable Size | C2: 24 | D2: =SUMIFS($C$13:$DV$13,$C$9:$DV$9,C1,$C$12:$DV$12,C2) | G2: Cable Size | H2: 24 | I2: =SUMIFS($C$13:$BD$13,$C$9:$BD$9,H1,$C$12:$BD$12,H2) | L2: Cable Size | M2: 24 | N2: =SUMIFS($C$13:$BD$13,$C$9:$BD$9,M1,$C$12:$BD$12,M2) | Q2: 15 FOR SPLT
C3: 48 | D3: =SUMIFS($C$13:$DV$13,$C$9:$DV$9,C1,$C$12:$DV$12,C3) | H3: 48 | I3: =SUMIFS($C$13:$BD$13,$C$9:$BD$9,H1,$C$12:$BD$12,H3) | M3: 48 | N3: =SUMIFS($C$13:$BD$13,$C$9:$BD$9,M1,$C$12:$BD$12,M3) | Q3: 50 FOR ALL ELSE
C4: 96 | D4: =SUMIFS($C$13:$DV$13,$C$9:$DV$9,C1,$C$12:$DV$12,C4) | H4: 96 | I4: =SUMIFS($C$13:$BD$13,$C$9:$BD$9,H1,$C$12:$BD$12,H4) | M4: 96 | N4: =SUMIFS($C$13:$BD$13,$C$9:$BD$9,M1,$C$12:$BD$12,M4) | Q4: FIRST ROW 0 AND THE HANDHOLE STORAGE OF HH IT STARTS FROM
C5: 144 | D5: =SUMIFS($C$13:$DV$13,$C$9:$DV$9,C1,$C$12:$DV$12,C5) | H5: 144 | I5: =SUMIFS($C$13:$BD$13,$C$9:$BD$9,H1,$C$12:$BD$12,H5) | M5: 144 | N5: =SUMIFS($C$13:$BD$13,$C$9:$BD$9,M1,$C$12:$BD$12,M5)
C6: 288 | D6: =SUMIFS($C$13:$DV$13,$C$9:$DV$9,C1,$C$12:$DV$12,C6) | H6: 288 | I6: =SUMIFS($C$13:$BD$13,$C$9:$BD$9,H1,$C$12:$BD$12,H6) | M6: 288 | N6: =SUMIFS($C$13:$BD$13,$C$9:$BD$9,M1,$C$12:$BD$12,M6)
C7: 432 | D7: =SUMIFS($C$13:$DF$13,$C$9:$DF$9,C1,$C$12:$DF$12,C7) | H7: 432 | I7: =SUMIFS($C$13:$DF$13,$C$9:$DF$9,H1,$C$12:$DF$12,H7) | M7: 432 | N7: =SUMIFS($C$13:$DF$13,$C$9:$DF$9,M1,$C$12:$DF$12,M7)
B9: SEG 1 | C9: New Conduit | G9: SEG 2 | H9: New Conduit | L9: SEG 3 | M9: New Conduit | Q9: SEG 4 | R9: New Conduit | V9: SEG 5 | W9: New Conduit | AA9: SEG 6 | AB9: New Conduit | AF9: SEG 7 | AG9: New Conduit | AK9: SEG 8 | AL9: New Conduit | AP9: SEG 9 | AQ9: New Conduit | AU9: SEG 10 | AV9: New Conduit | AZ9: SEG 11 | BA9: New Conduit | BE9: SEG 12 | BF9: New Conduit | BJ9: SEG 13 | BK9: New Conduit | BO9: SEG 14 | BP9: New Conduit | BT9: SEG 15 | BU9: New Conduit | BY9: SEG 16 | BZ9: New Conduit | CD9: SEG 17 | CE9: New Conduit | CI9: SEG 18 | CJ9: New Conduit | CN9: SEG 19 | CO9: New Conduit | CS9: SEG 20 | CT9: New Conduit | CX9: SEG 21 | CY9: New Conduit | DC9: SEG 22 | DD9: New Conduit | DH9: SEG 23 | DI9: New Conduit | DM9: SEG 24 | DR9: SEG 25
B10: START | G10: START | L10: START | Q10: START | V10: START | AA10: START | AF10: START | AK10: START | AP10: START | AU10: START | AZ10: START | BE10: START | BJ10: START | BO10: START | BT10: START | BY10: START | CD10: START | CI10: START | CN10: START | CS10: START | CX10: START | DC10: START | DH10: START | DM10: START | DR10: START
B11: END | G11: END | L11: END | Q11: END | V11: END | AA11: END | AF11: END | AK11: END | AP11: END | AU11: END | AZ11: END | BE11: END | BJ11: END | BO11: END | BT11: END | BY11: END | CD11: END | CI11: END | CN11: END | CS11: END | CX11: END | DC11: END | DH11: END | DM11: END | DR11: END
B12: CABLE SIZE | G12: CABLE SIZE | L12: CABLE SIZE | Q12: CABLE SIZE | V12: CABLE SIZE | AA12: CABLE SIZE | AF12: CABLE SIZE | AK12: CABLE SIZE | AP12: CABLE SIZE | AU12: CABLE SIZE | AZ12: CABLE SIZE | BE12: CABLE SIZE | BJ12: CABLE SIZE | BO12: CABLE SIZE | BT12: CABLE SIZE | BY12: CABLE SIZE | CD12: CABLE SIZE | CI12: CABLE SIZE | CN12: CABLE SIZE | CS12: CABLE SIZE | CX12: CABLE SIZE | DC12: CABLE SIZE | DH12: CABLE SIZE | DM12: CABLE SIZE | DR12: CABLE SIZE
B13: TOTAL | C13: =SUM(C15:E201) | G13: TOTAL | H13: =SUM(H15:J201) | L13: TOTAL | M13: =SUM(M15:O201) | Q13: TOTAL | R13: =SUM(R15:T201) | V13: TOTAL | W13: =SUM(W15:Y201) | AA13: TOTAL | AB13: =SUM(AB15:AD201) | AF13: TOTAL | AG13: =SUM(AG15:AI201) | AK13: TOTAL | AL13: =SUM(AL15:AN201) | AP13: TOTAL | AQ13: =SUM(AQ15:AS201) | AU13: TOTAL | AV13: =SUM(AV15:AX201) | AZ13: TOTAL | BA13: =SUM(BA15:BC201) | BE13: TOTAL | BF13: =SUM(BF15:BH201) | BJ13: TOTAL | BK13: =SUM(BK15:BM201) | BO13: TOTAL | BP13: =SUM(BP15:BR201) | BT13: TOTAL | BU13: =SUM(BU15:BW201) | BY13: TOTAL | BZ13: =SUM(BZ15:CB201) | CD13: TOTAL | CE13: =SUM(CE15:CG201) | CI13: TOTAL | CJ13: =SUM(CJ15:CL201) | CN13: TOTAL | CO13: =SUM(CO15:CQ201) | CS13: TOTAL | CT13: =SUM(CT15:CV201) | CX13: TOTAL | CY13: =SUM(CY15:DA201) | DC13: TOTAL | DD13: =SUM(DD15:DF201) | DH13: TOTAL | DI13: =SUM(DI15:DK201) | DM13: TOTAL | DN13: =SUM(DN15:DP201) | DR13: TOTAL | DS13: =SUM(DS15:DU201)
C14: SPAN | D14: STORAGE | E14: RISER | H14: SPAN | I14: STORAGE | J14: RISER | M14: SPAN | N14: STORAGE | O14: RISER | R14: SPAN | S14: STORAGE | T14: RISER | W14: SPAN | X14: STORAGE | Y14: RISER | AB14: SPAN | AC14: STORAGE | AD14: RISER | AG14: SPAN | AH14: STORAGE | AI14: RISER | AL14: SPAN | AM14: STORAGE | AN14: RISER | AQ14: SPAN | AR14: STORAGE | AS14: RISER | AV14: SPAN | AW14: STORAGE | AX14: RISER | BA14: SPAN | BB14: STORAGE | BC14: RISER | BF14: SPAN | BG14: STORAGE | BH14: RISER | BK14: SPAN | BL14: STORAGE | BM14: RISER | BP14: SPAN | BQ14: STORAGE | BR14: RISER | BU14: SPAN | BV14: STORAGE | BW14: RISER | BZ14: SPAN | CA14: STORAGE | CB14: RISER | CE14: SPAN | CF14: STORAGE | CG14: RISER | CJ14: SPAN | CK14: STORAGE | CL14: RISER | CO14: SPAN | CP14: STORAGE | CQ14: RISER | CT14: SPAN | CU14: STORAGE | CV14: RISER | CY14: SPAN | CZ14: STORAGE | DA14: RISER | DD14: SPAN | DE14: STORAGE | DF14: RISER | DI14: SPAN | DJ14: STORAGE | DK14: RISER | DN14: SPAN | DO14: STORAGE | DP14: RISER | DS14: SPAN | DT14: STORAGE | DU14: RISER
C15: 0 | D15: 50

Sheet LABOR SPAN SHEET
J1: UNIT 140 NEW AERIAL | K1: UNIT 141 OVERLASH | L1: UNIT 141 OVERLASH | M1: UNIT 141 OVERLASH | N1: UNIT 146 OL MP ONLY | O1: UNIT 148 PLACE RDF or SELFSUPPORT MP TAIL | Q1: TOTAL FOOTAGE UNIT 147 | S1: =SUM(Q2:Y2) | AA1: UNIT 220 | AB1: UNIT 210 | AD1: UNIT 200 | AE1: UNIT 5 | AF1: UNIT 5
C2: TOTAL FOOTAGES | J2: =SUM(J7:J1000) | K2: =SUM(K7:K1000) | L2: =SUM(L7:L1000) | M2: =SUM(M7:M1000) | N2: =SUM(N7:N1000) | O2: =SUM(O7:O1000) | P2: TOTAL SPAN * NUMBER MP | Q2: =Q3*Q4 | R2: =R3*R4 | S2: =S3*S4 | T2: =T3*T4 | U2: =U3*U4 | V2: =V3*V4 | W2: =W3*W4 | X2: =X3*X4 | Y2: =Y3*Y4 | AA2: =SUM(AA7:AA1000) | AB2: =SUM(AB7:AB1000) | AD2: =SUM(AD7:AD1000) | AE2: =SUM(AE7:AE1000) | AF2: =SUM(AF7:AF1000) | AG2: =SUM(AG7:AG1000)
P3: SPAN FOOTAGE | Q3: =SUM(Q7:Q404) | R3: =SUM(R7:R404) | S3: =SUM(S7:S404) | T3: =SUM(T7:T404) | U3: =SUM(U7:U404) | V3: =SUM(V7:V404) | W3: =SUM(W7:W404) | X3: =SUM(X7:X404) | Y3: =SUM(Y7:Y404) | BZ3: 1 | CB3: 1
P4: NUMBER OF MP PER SPAN | Q4: 1 | R4: 2 | S4: 3 | T4: 4 | U4: 5 | V4: 6 | W4: 7 | X4: 8 | Y4: 9 | BZ4: 2 | CB4: 2
K5: CABLE ONLY OR WITH MP TAILS | M5: MPS 2 AND 3 | N5: USE FOR 1ST MP | Q5: THESE COUNTS ARE AFTER SUBTRACTING 2 MP'S THAT WOULD BE INCLUDED WITH NEW BUILD OR OVBER LASH. OR AFTER THE FIRST MP ONLY OVERLASH. COUNTING ONLY UNIT 127 | AD5: UNIT 200 | AE5: UNIT 5 | AF5: UNIT 5
A6: JOB PRINT PAGE # | B6: Construction Note Letter Job Print | C6: SPAN FOOTAGE | D6: NON-STANDARD CONDUIT SIZE | E6: IS THIS A PARALLELING DROP CONDUIT? | F6: CABLES THIS SPAN | G6: NEW CONDUIT THIS SPAN ONLY (UP TO 2) | H6: *ADDITIONAL* NEW CONDUIT 3RD & 4TH CONDUIT (UP TO 2) | I6: *ADDITIONAL* NEW CONDUIT 5TH CONDUIT (UP TO 1) | J6: NEW AERIAL Cable INCLUDES 2 MP TAILS | K6: OVERLASH CABLE INCLUDES 2 MP TAILS | L6: OVERLASH 2ND CABLE | M6: OVERLASH MPS ONLY (USE FOR MP 2 AND 3) | N6: OVERLASH MP TAIL ONLY 1ST MP TAIL | O6: SELF SUPPORT MP TAILS OR RDF | Q6: 1 MP | R6: 2 MP'S | S6: 3 MP'S | T6: 4 MP'S | U6: 5 MP'S | V6: 6 MP'S | W6: 7 MP'S | X6: 8 MP'S | Y6: 9 MP'S | AA6: PULL IN EXISTING CONDUIT | AB6: PULL ADDITIONAL FIBER (AFTER 2ND FIBER) | AD6: NEW BURIED (INCLUDES UP TO 2 CONDUITS) | AE6: *ADDITIONAL* NEW BURIED (INCLUDES 3RD AND 4TH CONDUITS) | AF6: *ADDITIONAL* NEW BURIED (5TH CONDUIT) | AG6: CONDUIT MATERIAL QUANTITY TO BE ORDERED
AA7: =IF(G7=0, IF(OR(H7>0,F7>0),C7*F7,""),"") | AB7: =IF(G7>=1,IF(F7>1,C7*(F7-2),""),"") | AD7: =IF(E7="YES",IF(G7=1,"",""),IF(G7=1,C7,IF(G7=2,C7,IF(G7=0,"","")))) | AE7: =IF(E7="YES",IF(G7=1,"",IF(H7=1,C7,"")),IF(H7=1,C7,IF(H7=2,C7,IF(H7=0,"","")))) | AF7: =IF(E7="YES",IF(I7=1,C7,""),IF(I7=1,C7,IF(I7=2,C7,IF(I7=0,"","")))) | AG7: =(C7*G7)+(C7*H7)+(C7*I7)
AA8: =IF(G8=0, IF(OR(H8>0,F8>0),C8*F8,""),"") | AB8: =IF(G8>=1,IF(F8>1,C8*(F8-2),""),"") | AD8: =IF(E8="YES",IF(G8=1,"",""),IF(G8=1,C8,IF(G8=2,C8,IF(G8=0,"","")))) | AE8: =IF(E8="YES",IF(G8=1,"",IF(H8=1,C8,"")),IF(H8=1,C8,IF(H8=2,C8,IF(H8=0,"","")))) | AF8: =IF(E8="YES",IF(I8=1,C8,""),IF(I8=1,C8,IF(I8=2,C8,IF(I8=0,"","")))) | AG8: =(C8*G8)+(C8*H8)+(C8*I8)
AA9: =IF(G9=0, IF(OR(H9>0,F9>0),C9*F9,""),"") | AB9: =IF(G9>=1,IF(F9>1,C9*(F9-2),""),"") | AD9: =IF(E9="YES",IF(G9=1,"",""),IF(G9=1,C9,IF(G9=2,C9,IF(G9=0,"","")))) | AE9: =IF(E9="YES",IF(G9=1,"",IF(H9=1,C9,"")),IF(H9=1,C9,IF(H9=2,C9,IF(H9=0,"","")))) | AF9: =IF(E9="YES",IF(I9=1,C9,""),IF(I9=1,C9,IF(I9=2,C9,IF(I9=0,"","")))) | AG9: =(C9*G9)+(C9*H9)+(C9*I9)
AA10: =IF(G10=0, IF(OR(H10>0,F10>0),C10*F10,""),"") | AB10: =IF(G10>=1,IF(F10>1,C10*(F10-2),""),"") | AD10: =IF(E10="YES",IF(G10=1,"",""),IF(G10=1,C10,IF(G10=2,C10,IF(G10=0,"","")))) | AE10: =IF(E10="YES",IF(G10=1,"",IF(H10=1,C10,"")),IF(H10=1,C10,IF(H10=2,C10,IF(H10=0,"","")))) | AF10: =IF(E10="YES",IF(I10=1,C10,""),IF(I10=1,C10,IF(I10=2,C10,IF(I10=0,"","")))) | AG10: =(C10*G10)+(C10*H10)+(C10*I10)
AA11: =IF(G11=0, IF(OR(H11>0,F11>0),C11*F11,""),"") | AB11: =IF(G11>=1,IF(F11>1,C11*(F11-2),""),"") | AD11: =IF(E11="YES",IF(G11=1,"",""),IF(G11=1,C11,IF(G11=2,C11,IF(G11=0,"","")))) | AE11: =IF(E11="YES",IF(G11=1,"",IF(H11=1,C11,"")),IF(H11=1,C11,IF(H11=2,C11,IF(H11=0,"","")))) | AF11: =IF(E11="YES",IF(I11=1,C11,""),IF(I11=1,C11,IF(I11=2,C11,IF(I11=0,"","")))) | AG11: =(C11*G11)+(C11*H11)+(C11*I11)
AA12: =IF(G12=0, IF(OR(H12>0,F12>0),C12*F12,""),"") | AB12: =IF(G12>=1,IF(F12>1,C12*(F12-2),""),"") | AD12: =IF(E12="YES",IF(G12=1,"",""),IF(G12=1,C12,IF(G12=2,C12,IF(G12=0,"","")))) | AE12: =IF(E12="YES",IF(G12=1,"",IF(H12=1,C12,"")),IF(H12=1,C12,IF(H12=2,C12,IF(H12=0,"","")))) | AF12: =IF(E12="YES",IF(I12=1,C12,""),IF(I12=1,C12,IF(I12=2,C12,IF(I12=0,"","")))) | AG12: =(C12*G12)+(C12*H12)+(C12*I12)
AA13: =IF(G13=0, IF(OR(H13>0,F13>0),C13*F13,""),"") | AB13: =IF(G13>=1,IF(F13>1,C13*(F13-2),""),"") | AD13: =IF(E13="YES",IF(G13=1,"",""),IF(G13=1,C13,IF(G13=2,C13,IF(G13=0,"","")))) | AE13: =IF(E13="YES",IF(G13=1,"",IF(H13=1,C13,"")),IF(H13=1,C13,IF(H13=2,C13,IF(H13=0,"","")))) | AF13: =IF(E13="YES",IF(I13=1,C13,""),IF(I13=1,C13,IF(I13=2,C13,IF(I13=0,"","")))) | AG13: =(C13*G13)+(C13*H13)+(C13*I13)
AA14: =IF(G14=0, IF(OR(H14>0,F14>0),C14*F14,""),"") | AB14: =IF(G14>=1,IF(F14>1,C14*(F14-2),""),"") | AD14: =IF(E14="YES",IF(G14=1,"",""),IF(G14=1,C14,IF(G14=2,C14,IF(G14=0,"","")))) | AE14: =IF(E14="YES",IF(G14=1,"",IF(H14=1,C14,"")),IF(H14=1,C14,IF(H14=2,C14,IF(H14=0,"","")))) | AF14: =IF(E14="YES",IF(I14=1,C14,""),IF(I14=1,C14,IF(I14=2,C14,IF(I14=0,"","")))) | AG14: =(C14*G14)+(C14*H14)+(C14*I14)
AA15: =IF(G15=0, IF(OR(H15>0,F15>0),C15*F15,""),"") | AB15: =IF(G15>=1,IF(F15>1,C15*(F15-2),""),"") | AD15: =IF(E15="YES",IF(G15=1,"",""),IF(G15=1,C15,IF(G15=2,C15,IF(G15=0,"","")))) | AE15: =IF(E15="YES",IF(G15=1,"",IF(H15=1,C15,"")),IF(H15=1,C15,IF(H15=2,C15,IF(H15=0,"","")))) | AF15: =IF(E15="YES",IF(I15=1,C15,""),IF(I15=1,C15,IF(I15=2,C15,IF(I15=0,"","")))) | AG15: =(C15*G15)+(C15*H15)+(C15*I15)
AA16: =IF(G16=0, IF(OR(H16>0,F16>0),C16*F16,""),"") | AB16: =IF(G16>=1,IF(F16>1,C16*(F16-2),""),"") | AD16: =IF(E16="YES",IF(G16=1,"",""),IF(G16=1,C16,IF(G16=2,C16,IF(G16=0,"","")))) | AE16: =IF(E16="YES",IF(G16=1,"",IF(H16=1,C16,"")),IF(H16=1,C16,IF(H16=2,C16,IF(H16=0,"","")))) | AF16: =IF(E16="YES",IF(I16=1,C16,""),IF(I16=1,C16,IF(I16=2,C16,IF(I16=0,"","")))) | AG16: =(C16*G16)+(C16*H16)+(C16*I16)
AA17: =IF(G17=0, IF(OR(H17>0,F17>0),C17*F17,""),"") | AB17: =IF(G17>=1,IF(F17>1,C17*(F17-2),""),"") | AD17: =IF(E17="YES",IF(G17=1,"",""),IF(G17=1,C17,IF(G17=2,C17,IF(G17=0,"","")))) | AE17: =IF(E17="YES",IF(G17=1,"",IF(H17=1,C17,"")),IF(H17=1,C17,IF(H17=2,C17,IF(H17=0,"","")))) | AF17: =IF(E17="YES",IF(I17=1,C17,""),IF(I17=1,C17,IF(I17=2,C17,IF(I17=0,"","")))) | AG17: =(C17*G17)+(C17*H17)+(C17*I17)
AA18: =IF(G18=0, IF(OR(H18>0,F18>0),C18*F18,""),"") | AB18: =IF(G18>=1,IF(F18>1,C18*(F18-2),""),"") | AD18: =IF(E18="YES",IF(G18=1,"",""),IF(G18=1,C18,IF(G18=2,C18,IF(G18=0,"","")))) | AE18: =IF(E18="YES",IF(G18=1,"",IF(H18=1,C18,"")),IF(H18=1,C18,IF(H18=2,C18,IF(H18=0,"","")))) | AF18: =IF(E18="YES",IF(I18=1,C18,""),IF(I18=1,C18,IF(I18=2,C18,IF(I18=0,"","")))) | AG18: =(C18*G18)+(C18*H18)+(C18*I18)
... AA1342: =IF(G1342=0, IF(OR(H1342>0,F1342>0),C1342*F1342,""),"") | AB1342: =IF(G1342>=1,IF(F1342>1,C1342*(F1342-2),""),"") | AD1342: =IF(E1342="YES",IF(G1342=1,"",""),IF(G1342=1,C1342,IF(G1342=2,C1342,IF(G1342=0,"","")))) | AE1342: =IF(E1342="YES",IF(G1342=1,"",IF(H1342=1,C1342,"")),IF(H1342=1,C1342,IF(H1342=2,C1342,IF(H1342=0,"","")))) | AF1342: =IF(E1342="YES",IF(I1342=1,C1342,""),IF(I1342=1,C1342,IF(I1342=2,C1342,IF(I1342=0,"","")))) | AG1342: =(C1342*G1342)+(C1342*H1342)+(C1342*I1342)
AB1343: =IF(G1343>=1,IF(F1343>1,C1343*(F1343-2),""),"") | AD1343: =IF(E1343="YES",IF(G1343=1,"",""),IF(G1343=1,C1343,IF(G1343=2,C1343,IF(G1343=0,"","")))) | AE1343: =IF(E1343="YES",IF(G1343=1,"",IF(H1343=1,C1343,"")),IF(H1343=1,C1343,IF(H1343=2,C1343,IF(H1343=0,"","")))) | AF1343: =IF(E1343="YES",IF(I1343=1,C1343,""),IF(I1343=1,C1343,IF(I1343=2,C1343,IF(I1343=0,"","")))) | AG1343: =(C1343*G1343)+(C1343*H1343)+(C1343*I1343)
AB1344: =IF(G1344>=1,IF(F1344>1,C1344*(F1344-2),""),"") | AD1344: =IF(E1344="YES",IF(G1344=1,"",""),IF(G1344=1,C1344,IF(G1344=2,C1344,IF(G1344=0,"","")))) | AE1344: =IF(E1344="YES",IF(G1344=1,"",IF(H1344=1,C1344,"")),IF(H1344=1,C1344,IF(H1344=2,C1344,IF(H1344=0,"","")))) | AF1344: =IF(E1344="YES",IF(I1344=1,C1344,""),IF(I1344=1,C1344,IF(I1344=2,C1344,IF(I1344=0,"","")))) | AG1344: =(C1344*G1344)+(C1344*H1344)+(C1344*I1344)
AB1345: =IF(G1345>=1,IF(F1345>1,C1345*(F1345-2),""),"") | AD1345: =IF(E1345="YES",IF(G1345=1,"",""),IF(G1345=1,C1345,IF(G1345=2,C1345,IF(G1345=0,"","")))) | AE1345: =IF(E1345="YES",IF(G1345=1,"",IF(H1345=1,C1345,"")),IF(H1345=1,C1345,IF(H1345=2,C1345,IF(H1345=0,"","")))) | AF1345: =IF(E1345="YES",IF(I1345=1,C1345,""),IF(I1345=1,C1345,IF(I1345=2,C1345,IF(I1345=0,"","")))) | AG1345: =(C1345*G1345)+(C1345*H1345)+(C1345*I1345)
AB1346: =IF(G1346>=1,IF(F1346>1,C1346*(F1346-2),""),"") | AD1346: =IF(E1346="YES",IF(G1346=1,"",""),IF(G1346=1,C1346,IF(G1346=2,C1346,IF(G1346=0,"","")))) | AE1346: =IF(E1346="YES",IF(G1346=1,"",IF(H1346=1,C1346,"")),IF(H1346=1,C1346,IF(H1346=2,C1346,IF(H1346=0,"","")))) | AF1346: =IF(E1346="YES",IF(I1346=1,C1346,""),IF(I1346=1,C1346,IF(I1346=2,C1346,IF(I1346=0,"","")))) | AG1346: =(C1346*G1346)+(C1346*H1346)+(C1346*I1346)
AB1347: =IF(G1347>=1,IF(F1347>1,C1347*(F1347-2),""),"") | AD1347: =IF(E1347="YES",IF(G1347=1,"",""),IF(G1347=1,C1347,IF(G1347=2,C1347,IF(G1347=0,"","")))) | AE1347: =IF(E1347="YES",IF(G1347=1,"",IF(H1347=1,C1347,"")),IF(H1347=1,C1347,IF(H1347=2,C1347,IF(H1347=0,"","")))) | AF1347: =IF(E1347="YES",IF(I1347=1,C1347,""),IF(I1347=1,C1347,IF(I1347=2,C1347,IF(I1347=0,"","")))) | AG1347: =(C1347*G1347)+(C1347*H1347)+(C1347*I1347)
AB1348: =IF(G1348>=1,IF(F1348>1,C1348*(F1348-2),""),"") | AD1348: =IF(E1348="YES",IF(G1348=1,"",""),IF(G1348=1,C1348,IF(G1348=2,C1348,IF(G1348=0,"","")))) | AE1348: =IF(E1348="YES",IF(G1348=1,"",IF(H1348=1,C1348,"")),IF(H1348=1,C1348,IF(H1348=2,C1348,IF(H1348=0,"","")))) | AF1348: =IF(E1348="YES",IF(I1348=1,C1348,""),IF(I1348=1,C1348,IF(I1348=2,C1348,IF(I1348=0,"","")))) | AG1348: =(C1348*G1348)+(C1348*H1348)+(C1348*I1348)
AB1349: =IF(G1349>=1,IF(F1349>1,C1349*(F1349-2),""),"") | AD1349: =IF(E1349="YES",IF(G1349=1,"",""),IF(G1349=1,C1349,IF(G1349=2,C1349,IF(G1349=0,"","")))) | AE1349: =IF(E1349="YES",IF(G1349=1,"",IF(H1349=1,C1349,"")),IF(H1349=1,C1349,IF(H1349=2,C1349,IF(H1349=0,"","")))) | AF1349: =IF(E1349="YES",IF(I1349=1,C1349,""),IF(I1349=1,C1349,IF(I1349=2,C1349,IF(I1349=0,"","")))) | AG1349: =(C1349*G1349)+(C1349*H1349)+(C1349*I1349)
AB1350: =IF(G1350>=1,IF(F1350>1,C1350*(F1350-2),""),"") | AD1350: =IF(E1350="YES",IF(G1350=1,"",""),IF(G1350=1,C1350,IF(G1350=2,C1350,IF(G1350=0,"","")))) | AE1350: =IF(E1350="YES",IF(G1350=1,"",IF(H1350=1,C1350,"")),IF(H1350=1,C1350,IF(H1350=2,C1350,IF(H1350=0,"","")))) | AF1350: =IF(E1350="YES",IF(I1350=1,C1350,""),IF(I1350=1,C1350,IF(I1350=2,C1350,IF(I1350=0,"","")))) | AG1350: =(C1350*G1350)+(C1350*H1350)+(C1350*I1350)
AB1351: =IF(G1351>=1,IF(F1351>1,C1351*(F1351-2),""),"") | AD1351: =IF(E1351="YES",IF(G1351=1,"",""),IF(G1351=1,C1351,IF(G1351=2,C1351,IF(G1351=0,"","")))) | AE1351: =IF(E1351="YES",IF(G1351=1,"",IF(H1351=1,C1351,"")),IF(H1351=1,C1351,IF(H1351=2,C1351,IF(H1351=0,"","")))) | AF1351: =IF(E1351="YES",IF(I1351=1,C1351,""),IF(I1351=1,C1351,IF(I1351=2,C1351,IF(I1351=0,"","")))) | AG1351: =(C1351*G1351)+(C1351*H1351)+(C1351*I1351)
AB1352: =IF(G1352>=1,IF(F1352>1,C1352*(F1352-2),""),"") | AD1352: =IF(E1352="YES",IF(G1352=1,"",""),IF(G1352=1,C1352,IF(G1352=2,C1352,IF(G1352=0,"","")))) | AE1352: =IF(E1352="YES",IF(G1352=1,"",IF(H1352=1,C1352,"")),IF(H1352=1,C1352,IF(H1352=2,C1352,IF(H1352=0,"","")))) | AF1352: =IF(E1352="YES",IF(I1352=1,C1352,""),IF(I1352=1,C1352,IF(I1352=2,C1352,IF(I1352=0,"","")))) | AG1352: =(C1352*G1352)+(C1352*H1352)+(C1352*I1352)
AB1353: =IF(G1353>=1,IF(F1353>1,C1353*(F1353-2),""),"") | AD1353: =IF(E1353="YES",IF(G1353=1,"",""),IF(G1353=1,C1353,IF(G1353=2,C1353,IF(G1353=0,"","")))) | AE1353: =IF(E1353="YES",IF(G1353=1,"",IF(H1353=1,C1353,"")),IF(H1353=1,C1353,IF(H1353=2,C1353,IF(H1353=0,"","")))) | AF1353: =IF(E1353="YES",IF(I1353=1,C1353,""),IF(I1353=1,C1353,IF(I1353=2,C1353,IF(I1353=0,"","")))) | AG1353: =(C1353*G1353)+(C1353*H1353)+(C1353*I1353)
AB1354: =IF(G1354>=1,IF(F1354>1,C1354*(F1354-2),""),"") | AD1354: =IF(E1354="YES",IF(G1354=1,"",""),IF(G1354=1,C1354,IF(G1354=2,C1354,IF(G1354=0,"","")))) | AE1354: =IF(E1354="YES",IF(G1354=1,"",IF(H1354=1,C1354,"")),IF(H1354=1,C1354,IF(H1354=2,C1354,IF(H1354=0,"","")))) | AF1354: =IF(E1354="YES",IF(I1354=1,C1354,""),IF(I1354=1,C1354,IF(I1354=2,C1354,IF(I1354=0,"","")))) | AG1354: =(C1354*G1354)+(C1354*H1354)+(C1354*I1354)
... AB1381: =IF(G1381>=1,IF(F1381>1,C1381*(F1381-2),""),"") | AD1381: =IF(E1381="YES",IF(G1381=1,"",""),IF(G1381=1,C1381,IF(G1381=2,C1381,IF(G1381=0,"","")))) | AE1381: =IF(E1381="YES",IF(G1381=1,"",IF(H1381=1,C1381,"")),IF(H1381=1,C1381,IF(H1381=2,C1381,IF(H1381=0,"","")))) | AF1381: =IF(E1381="YES",IF(I1381=1,C1381,""),IF(I1381=1,C1381,IF(I1381=2,C1381,IF(I1381=0,"","")))) | AG1381: =(C1381*G1381)+(C1381*H1381)+(C1381*I1381)
AD1382: =IF(E1382="YES",IF(G1382=1,"",""),IF(G1382=1,C1382,IF(G1382=2,C1382,IF(G1382=0,"","")))) | AE1382: =IF(E1382="YES",IF(G1382=1,"",IF(H1382=1,C1382,"")),IF(H1382=1,C1382,IF(H1382=2,C1382,IF(H1382=0,"","")))) | AF1382: =IF(E1382="YES",IF(I1382=1,C1382,""),IF(I1382=1,C1382,IF(I1382=2,C1382,IF(I1382=0,"","")))) | AG1382: =(C1382*G1382)+(C1382*H1382)+(C1382*I1382)
AD1383: =IF(E1383="YES",IF(G1383=1,"",""),IF(G1383=1,C1383,IF(G1383=2,C1383,IF(G1383=0,"","")))) | AE1383: =IF(E1383="YES",IF(G1383=1,"",IF(H1383=1,C1383,"")),IF(H1383=1,C1383,IF(H1383=2,C1383,IF(H1383=0,"","")))) | AF1383: =IF(E1383="YES",IF(I1383=1,C1383,""),IF(I1383=1,C1383,IF(I1383=2,C1383,IF(I1383=0,"","")))) | AG1383: =(C1383*G1383)+(C1383*H1383)+(C1383*I1383)
AD1384: =IF(E1384="YES",IF(G1384=1,"",""),IF(G1384=1,C1384,IF(G1384=2,C1384,IF(G1384=0,"","")))) | AE1384: =IF(E1384="YES",IF(G1384=1,"",IF(H1384=1,C1384,"")),IF(H1384=1,C1384,IF(H1384=2,C1384,IF(H1384=0,"","")))) | AF1384: =IF(E1384="YES",IF(I1384=1,C1384,""),IF(I1384=1,C1384,IF(I1384=2,C1384,IF(I1384=0,"",""))))
AD1385: =IF(E1385="YES",IF(G1385=1,"",""),IF(G1385=1,C1385,IF(G1385=2,C1385,IF(G1385=0,"","")))) | AE1385: =IF(E1385="YES",IF(G1385=1,"",IF(H1385=1,C1385,"")),IF(H1385=1,C1385,IF(H1385=2,C1385,IF(H1385=0,"","")))) | AF1385: =IF(E1385="YES",IF(I1385=1,C1385,""),IF(I1385=1,C1385,IF(I1385=2,C1385,IF(I1385=0,"",""))))
AD1386: =IF(E1386="YES",IF(G1386=1,"",""),IF(G1386=1,C1386,IF(G1386=2,C1386,IF(G1386=0,"","")))) | AE1386: =IF(E1386="YES",IF(G1386=1,"",IF(H1386=1,C1386,"")),IF(H1386=1,C1386,IF(H1386=2,C1386,IF(H1386=0,"","")))) | AF1386: =IF(E1386="YES",IF(I1386=1,C1386,""),IF(I1386=1,C1386,IF(I1386=2,C1386,IF(I1386=0,"",""))))
AD1387: =IF(E1387="YES",IF(G1387=1,"",""),IF(G1387=1,C1387,IF(G1387=2,C1387,IF(G1387=0,"","")))) | AE1387: =IF(E1387="YES",IF(G1387=1,"",IF(H1387=1,C1387,"")),IF(H1387=1,C1387,IF(H1387=2,C1387,IF(H1387=0,"","")))) | AF1387: =IF(E1387="YES",IF(I1387=1,C1387,""),IF(I1387=1,C1387,IF(I1387=2,C1387,IF(I1387=0,"",""))))
AD1388: =IF(E1388="YES",IF(G1388=1,"",""),IF(G1388=1,C1388,IF(G1388=2,C1388,IF(G1388=0,"","")))) | AE1388: =IF(E1388="YES",IF(G1388=1,"",IF(H1388=1,C1388,"")),IF(H1388=1,C1388,IF(H1388=2,C1388,IF(H1388=0,"","")))) | AF1388: =IF(E1388="YES",IF(I1388=1,C1388,""),IF(I1388=1,C1388,IF(I1388=2,C1388,IF(I1388=0,"",""))))
AD1389: =IF(E1389="YES",IF(G1389=1,"",""),IF(G1389=1,C1389,IF(G1389=2,C1389,IF(G1389=0,"","")))) | AE1389: =IF(E1389="YES",IF(G1389=1,"",IF(H1389=1,C1389,"")),IF(H1389=1,C1389,IF(H1389=2,C1389,IF(H1389=0,"","")))) | AF1389: =IF(E1389="YES",IF(I1389=1,C1389,""),IF(I1389=1,C1389,IF(I1389=2,C1389,IF(I1389=0,"",""))))
...

Sheet House Count
A1: FULL ADDRESS (Upper Case) | B1: CITY | C1: STATE | D1: ZIP CODE | E1: Unit Number | F1: HOUSE TYPE | G1: Drop Type | H1: Servicable (Y/N) | I1: Serviceability Notes | J1: RES | K1: BUS
A2: 5717 ACCIPITER CT | B2: GENERIC_CITY | C2: GENERIC_STATE | D2: 00000 | H2: Y | J2: =IF('House Count'!H2="Y",IF('House Count'!F2="RES-SFU",1,IF('House Count'!F2="RES-MDU",1,IF('House Count'!F2="RES-HOA",1,0))),0) | K2: =IF('House Count'!H2="Y",IF('House Count'!F2="COMM-SU",1,IF('House Count'!F2="COM-MTU",1,IF('House Count'!F2="ENT",1,0))),0)
A3: 5720 ACCIPITER CT | B3: GENERIC_CITY | C3: GENERIC_STATE | D3: 00000 | H3: Y | J3: =IF('House Count'!H3="Y",IF('House Count'!F3="RES-SFU",1,IF('House Count'!F3="RES-MDU",1,IF('House Count'!F3="RES-HOA",1,0))),0) | K3: =IF('House Count'!H3="Y",IF('House Count'!F3="COMM-SU",1,IF('House Count'!F3="COM-MTU",1,IF('House Count'!F3="ENT",1,0))),0)
A4: 5712 ACCIPITER CT | B4: GENERIC_CITY | C4: GENERIC_STATE | D4: 00000 | H4: Y | J4: =IF('House Count'!H4="Y",IF('House Count'!F4="RES-SFU",1,IF('House Count'!F4="RES-MDU",1,IF('House Count'!F4="RES-HOA",1,0))),0) | K4: =IF('House Count'!H4="Y",IF('House Count'!F4="COMM-SU",1,IF('House Count'!F4="COM-MTU",1,IF('House Count'!F4="ENT",1,0))),0)
A5: 5708 ACCIPITER CT | B5: GENERIC_CITY | C5: GENERIC_STATE | D5: 00000 | H5: Y | J5: =IF('House Count'!H5="Y",IF('House Count'!F5="RES-SFU",1,IF('House Count'!F5="RES-MDU",1,IF('House Count'!F5="RES-HOA",1,0))),0) | K5: =IF('House Count'!H5="Y",IF('House Count'!F5="COMM-SU",1,IF('House Count'!F5="COM-MTU",1,IF('House Count'!F5="ENT",1,0))),0)
A6: 5709 ACCIPITER CT | B6: GENERIC_CITY | C6: GENERIC_STATE | D6: 00000 | H6: Y | J6: =IF('House Count'!H6="Y",IF('House Count'!F6="RES-SFU",1,IF('House Count'!F6="RES-MDU",1,IF('House Count'!F6="RES-HOA",1,0))),0) | K6: =IF('House Count'!H6="Y",IF('House Count'!F6="COMM-SU",1,IF('House Count'!F6="COM-MTU",1,IF('House Count'!F6="ENT",1,0))),0)
A7: 5705 ACCIPITER CT | B7: GENERIC_CITY | C7: GENERIC_STATE | D7: 00000 | H7: Y | J7: =IF('House Count'!H7="Y",IF('House Count'!F7="RES-SFU",1,IF('House Count'!F7="RES-MDU",1,IF('House Count'!F7="RES-HOA",1,0))),0) | K7: =IF('House Count'!H7="Y",IF('House Count'!F7="COMM-SU",1,IF('House Count'!F7="COM-MTU",1,IF('House Count'!F7="ENT",1,0))),0)
A8: 5701 ACCIPITER CT | B8: GENERIC_CITY | C8: GENERIC_STATE | D8: 00000 | H8: Y | J8: =IF('House Count'!H8="Y",IF('House Count'!F8="RES-SFU",1,IF('House Count'!F8="RES-MDU",1,IF('House Count'!F8="RES-HOA",1,0))),0) | K8: =IF('House Count'!H8="Y",IF('House Count'!F8="COMM-SU",1,IF('House Count'!F8="COM-MTU",1,IF('House Count'!F8="ENT",1,0))),0)
A9: 5700 ACCIPITER CT | B9: GENERIC_CITY | C9: GENERIC_STATE | D9: 00000 | H9: Y | J9: =IF('House Count'!H9="Y",IF('House Count'!F9="RES-SFU",1,IF('House Count'!F9="RES-MDU",1,IF('House Count'!F9="RES-HOA",1,0))),0) | K9: =IF('House Count'!H9="Y",IF('House Count'!F9="COMM-SU",1,IF('House Count'!F9="COM-MTU",1,IF('House Count'!F9="ENT",1,0))),0)
A10: 5704 ACCIPITER CT | B10: GENERIC_CITY | C10: GENERIC_STATE | D10: 00000 | H10: Y | J10: =IF('House Count'!H10="Y",IF('House Count'!F10="RES-SFU",1,IF('House Count'!F10="RES-MDU",1,IF('House Count'!F10="RES-HOA",1,0))),0) | K10: =IF('House Count'!H10="Y",IF('House Count'!F10="COMM-SU",1,IF('House Count'!F10="COM-MTU",1,IF('House Count'!F10="ENT",1,0))),0)
A11: 6829 OLD MILLS RD | B11: GENERIC_CITY | C11: GENERIC_STATE | D11: 00000 | H11: Y | J11: =IF('House Count'!H11="Y",IF('House Count'!F11="RES-SFU",1,IF('House Count'!F11="RES-MDU",1,IF('House Count'!F11="RES-HOA",1,0))),0) | K11: =IF('House Count'!H11="Y",IF('House Count'!F11="COMM-SU",1,IF('House Count'!F11="COM-MTU",1,IF('House Count'!F11="ENT",1,0))),0)
A12: 6901 OLD MILLS RD | B12: GENERIC_CITY | C12: GENERIC_STATE | D12: 00000 | H12: Y | J12: =IF('House Count'!H12="Y",IF('House Count'!F12="RES-SFU",1,IF('House Count'!F12="RES-MDU",1,IF('House Count'!F12="RES-HOA",1,0))),0) | K12: =IF('House Count'!H12="Y",IF('House Count'!F12="COMM-SU",1,IF('House Count'!F12="COM-MTU",1,IF('House Count'!F12="ENT",1,0))),0)
A13: 6905 OLD MILLS RD | B13: GENERIC_CITY | C13: GENERIC_STATE | D13: 00000 | H13: Y | J13: =IF('House Count'!H13="Y",IF('House Count'!F13="RES-SFU",1,IF('House Count'!F13="RES-MDU",1,IF('House Count'!F13="RES-HOA",1,0))),0) | K13: =IF('House Count'!H13="Y",IF('House Count'!F13="COMM-SU",1,IF('House Count'!F13="COM-MTU",1,IF('House Count'!F13="ENT",1,0))),0)
... A325: 5204 HILLTOP NEEDMORE RD | B325: GENERIC_CITY | C325: GENERIC_STATE | D325: 00000 | H325: Y | J325: =IF('House Count'!H325="Y",IF('House Count'!F325="RES-SFU",1,IF('House Count'!F325="RES-MDU",1,IF('House Count'!F325="RES-HOA",1,0))),0) | K325: =IF('House Count'!H325="Y",IF('House Count'!F325="COMM-SU",1,IF('House Count'!F325="COM-MTU",1,IF('House Count'!F325="ENT",1,0))),0)
J326: =IF('House Count'!H326="Y",IF('House Count'!F326="RES-SFU",1,IF('House Count'!F326="RES-MDU",1,IF('House Count'!F326="RES-HOA",1,0))),0) | K326: =IF('House Count'!H326="Y",IF('House Count'!F326="COMM-SU",1,IF('House Count'!F326="COM-MTU",1,IF('House Count'!F326="ENT",1,0))),0)
J327: =IF('House Count'!H327="Y",IF('House Count'!F327="RES-SFU",1,IF('House Count'!F327="RES-MDU",1,IF('House Count'!F327="RES-HOA",1,0))),0) | K327: =IF('House Count'!H327="Y",IF('House Count'!F327="COMM-SU",1,IF('House Count'!F327="COM-MTU",1,IF('House Count'!F327="ENT",1,0))),0)
J328: =IF('House Count'!H328="Y",IF('House Count'!F328="RES-SFU",1,IF('House Count'!F328="RES-MDU",1,IF('House Count'!F328="RES-HOA",1,0))),0) | K328: =IF('House Count'!H328="Y",IF('House Count'!F328="COMM-SU",1,IF('House Count'!F328="COM-MTU",1,IF('House Count'!F328="ENT",1,0))),0)
J329: =IF('House Count'!H329="Y",IF('House Count'!F329="RES-SFU",1,IF('House Count'!F329="RES-MDU",1,IF('House Count'!F329="RES-HOA",1,0))),0) | K329: =IF('House Count'!H329="Y",IF('House Count'!F329="COMM-SU",1,IF('House Count'!F329="COM-MTU",1,IF('House Count'!F329="ENT",1,0))),0)
J330: =IF('House Count'!H330="Y",IF('House Count'!F330="RES-SFU",1,IF('House Count'!F330="RES-MDU",1,IF('House Count'!F330="RES-HOA",1,0))),0) | K330: =IF('House Count'!H330="Y",IF('House Count'!F330="COMM-SU",1,IF('House Count'!F330="COM-MTU",1,IF('House Count'!F330="ENT",1,0))),0)
J331: =IF('House Count'!H331="Y",IF('House Count'!F331="RES-SFU",1,IF('House Count'!F331="RES-MDU",1,IF('House Count'!F331="RES-HOA",1,0))),0) | K331: =IF('House Count'!H331="Y",IF('House Count'!F331="COMM-SU",1,IF('House Count'!F331="COM-MTU",1,IF('House Count'!F331="ENT",1,0))),0)
J332: =IF('House Count'!H332="Y",IF('House Count'!F332="RES-SFU",1,IF('House Count'!F332="RES-MDU",1,IF('House Count'!F332="RES-HOA",1,0))),0) | K332: =IF('House Count'!H332="Y",IF('House Count'!F332="COMM-SU",1,IF('House Count'!F332="COM-MTU",1,IF('House Count'!F332="ENT",1,0))),0)
J333: =IF('House Count'!H333="Y",IF('House Count'!F333="RES-SFU",1,IF('House Count'!F333="RES-MDU",1,IF('House Count'!F333="RES-HOA",1,0))),0) | K333: =IF('House Count'!H333="Y",IF('House Count'!F333="COMM-SU",1,IF('House Count'!F333="COM-MTU",1,IF('House Count'!F333="ENT",1,0))),0)
J334: =IF('House Count'!H334="Y",IF('House Count'!F334="RES-SFU",1,IF('House Count'!F334="RES-MDU",1,IF('House Count'!F334="RES-HOA",1,0))),0) | K334: =IF('House Count'!H334="Y",IF('House Count'!F334="COMM-SU",1,IF('House Count'!F334="COM-MTU",1,IF('House Count'!F334="ENT",1,0))),0)
J335: =IF('House Count'!H335="Y",IF('House Count'!F335="RES-SFU",1,IF('House Count'!F335="RES-MDU",1,IF('House Count'!F335="RES-HOA",1,0))),0) | K335: =IF('House Count'!H335="Y",IF('House Count'!F335="COMM-SU",1,IF('House Count'!F335="COM-MTU",1,IF('House Count'!F335="ENT",1,0))),0)
J336: =IF('House Count'!H336="Y",IF('House Count'!F336="RES-SFU",1,IF('House Count'!F336="RES-MDU",1,IF('House Count'!F336="RES-HOA",1,0))),0) | K336: =IF('House Count'!H336="Y",IF('House Count'!F336="COMM-SU",1,IF('House Count'!F336="COM-MTU",1,IF('House Count'!F336="ENT",1,0))),0)
J337: =IF('House Count'!H337="Y",IF('House Count'!F337="RES-SFU",1,IF('House Count'!F337="RES-MDU",1,IF('House Count'!F337="RES-HOA",1,0))),0) | K337: =IF('House Count'!H337="Y",IF('House Count'!F337="COMM-SU",1,IF('House Count'!F337="COM-MTU",1,IF('House Count'!F337="ENT",1,0))),0)
... J1513: =IF('House Count'!H1513="Y",IF('House Count'!F1513="RES-SFU",1,IF('House Count'!F1513="RES-MDU",1,IF('House Count'!F1513="RES-HOA",1,0))),0) | K1513: =IF('House Count'!H1513="Y",IF('House Count'!F1513="COMM-SU",1,IF('House Count'!F1513="COM-MTU",1,IF('House Count'!F1513="ENT",1,0))),0)

Sheet MEW
A1: Material Estimate Worksheet
A3: Move Order # | D3: Job Description: | F3: ='COVER SHEET'!B3
A4: Job #: | B4: ='COVER SHEET'!F4 | D4: Branch Plant: | H4: LUMOS Employee Signature | J4: Date
A5: Capital Bud. #: | D5: Engineer: | F5: ='COVER SHEET'!F2:G2
A6: Date: | D6: Tax District:
H7: Contractor Name & Signature | J7: Date
A8: Account | C8: Actual | D8: Reel | H8: Sub Total | I8: Material | J8: Quantity | K8: Document
A9: Code | B9: Quantity | C9: Quantity | D9: Number | E9: Item No. | F9: Description | G9: Cost | H9: Cost | I9: Trans Loc | J9: Returned | K9: Number
A10: {=_xlfn._xlws.FILTER(MATERIAL!A6:H341,(MATERIAL!B6:B341<>"")*(MATERIAL!B6:B341<>0)*(MATERIAL!B6:B341<>"-"))}
F70: Sub-Total | H70: =SUM(H10:H69) | I70: NOTES:
F71: Provisioning (10%) & Tax (5%) | H71: =H70*(MATERIAL!H1+MATERIAL!H2)
F72: Total Material Cost | H72: =H70+H71
A74: Account Code | B74: Good | C74: Worthless | E74: Item No. | F74: Description of Material Recovered

Sheet CABLE TO 1X8 SPLICING
A1: CABLE_1
A3: OLT | E3: ADDRESS | F3: 1X8 SPLITTER NAME | G3: PORT 1 | H3: PORT 2 | I3: PORT 3 | J3: PORT 4 | K3: PORT 5 | L3: PORT 6 | M3: PORT 7 | N3: PORT 8
A5: 1 | F5: =IF(G5<>"",LEFT(G5,FIND(",",G5)-1),"")
A6: 2 | F6: =IF(G6<>"",LEFT(G6,FIND(",",G6)-1),"")
A7: 3 | F7: =IF(G7<>"",LEFT(G7,FIND(",",G7)-1),"")
A8: 4 | F8: =IF(G8<>"",LEFT(G8,FIND(",",G8)-1),"")
A9: 5 | F9: =IF(G9<>"",LEFT(G9,FIND(",",G9)-1),"")
A10: 6 | F10: =IF(G10<>"",LEFT(G10,FIND(",",G10)-1),"")
A11: 7 | F11: =IF(G11<>"",LEFT(G11,FIND(",",G11)-1),"")
A12: 8 | F12: =IF(G12<>"",LEFT(G12,FIND(",",G12)-1),"")
A13: 9 | F13: =IF(G13<>"",LEFT(G13,FIND(",",G13)-1),"")
A14: 10 | F14: =IF(G14<>"",LEFT(G14,FIND(",",G14)-1),"")
A15: 11 | F15: =IF(G15<>"",LEFT(G15,FIND(",",G15)-1),"")
A16: 12 | F16: =IF(G16<>"",LEFT(G16,FIND(",",G16)-1),"")
... A89: 85 | F89: =IF(G89<>"",LEFT(G89,FIND(",",G89)-1),"")
A90: 86
A91: 87
A92: 88
A93: 89
A94: 90
A95: 91
A96: 92
A97: 93
A98: 94
A99: 95
A100: 96
A101: 97
... A104: 100
A105: 101 | D105: 101 | E105: F 5120 HILLTOP NEEDMORE RD | F105: OLT01_101P_FQVRNC | G105: OLT01_101P_FQVRNC, 1 (OLT01_101P_FQVRNC-1) | H105: OLT01_101P_FQVRNC, 2 (OLT01_101P_FQVRNC-2) | I105: OLT01_101P_FQVRNC, 3 (OLT01_101P_FQVRNC-3) | J105: OLT01_101P_FQVRNC, 4 (OLT01_101P_FQVRNC-4) | K105: OLT01_101P_FQVRNC, 5 (OLT01_101P_FQVRNC-5) | L105: OLT01_101P_FQVRNC, 6 (OLT01_101P_FQVRNC-6) | M105: OLT01_101P_FQVRNC, 7 (OLT01_101P_FQVRNC-7) | N105: OLT01_101P_FQVRNC, 8 (OLT01_101P_FQVRNC-8)
A106: 102 | D106: 102 | E106: F 5120 HILLTOP NEEDMORE RD | F106: OLT01_102P_FQVRNC | G106: OLT01_102P_FQVRNC, 1 (OLT01_102P_FQVRNC-1) | H106: OLT01_102P_FQVRNC, 2 (OLT01_102P_FQVRNC-2) | I106: OLT01_102P_FQVRNC, 3 (OLT01_102P_FQVRNC-3) | J106: OLT01_102P_FQVRNC, 4 (OLT01_102P_FQVRNC-4) | K106: OLT01_102P_FQVRNC, 5 (OLT01_102P_FQVRNC-5) | L106: OLT01_102P_FQVRNC, 6 (OLT01_102P_FQVRNC-6) | M106: OLT01_102P_FQVRNC, 7 (OLT01_102P_FQVRNC-7) | N106: OLT01_102P_FQVRNC, 8 (OLT01_102P_FQVRNC-8)
A107: 103 | D107: 103 | E107: F 5212 RIVINGTON DR | F107: OLT01_103P_FQVRNC | G107: SPARE | H107: SPARE | I107: OLT01_103P_FQVRNC, 3 (OLT01_103P_FQVRNC-3) | J107: OLT01_103P_FQVRNC, 4 (OLT01_103P_FQVRNC-4) | K107: OLT01_103P_FQVRNC, 5 (OLT01_103P_FQVRNC-5) | L107: OLT01_103P_FQVRNC, 6 (OLT01_103P_FQVRNC-6) | M107: OLT01_103P_FQVRNC, 7 (OLT01_103P_FQVRNC-7) | N107: OLT01_103P_FQVRNC, 8 (OLT01_103P_FQVRNC-8)
A108: 104 | D108: 104 | E108: F 5212 RIVINGTON DR | F108: OLT01_104P_FQVRNC | G108: OLT01_104P_FQVRNC, 1 (OLT01_104P_FQVRNC-1) | H108: OLT01_104P_FQVRNC, 2 (OLT01_104P_FQVRNC-2) | I108: OLT01_104P_FQVRNC, 3 (OLT01_104P_FQVRNC-3) | J108: OLT01_104P_FQVRNC, 4 (OLT01_104P_FQVRNC-4) | K108: OLT01_104P_FQVRNC, 5 (OLT01_104P_FQVRNC-5) | L108: OLT01_104P_FQVRNC, 6 (OLT01_104P_FQVRNC-6) | M108: OLT01_104P_FQVRNC, 7 (OLT01_104P_FQVRNC-7) | N108: OLT01_104P_FQVRNC, 8 (OLT01_104P_FQVRNC-8)
A109: 105 | D109: 105 | E109: F 7800 ST ANNES WAY | F109: OLT01_105P_FQVRNC | G109: SPARE | H109: OLT01_105P_FQVRNC, 2 (OLT01_105P_FQVRNC-2) | I109: OLT01_105P_FQVRNC, 3 (OLT01_105P_FQVRNC-3) | J109: OLT01_105P_FQVRNC, 4 (OLT01_105P_FQVRNC-4) | K109: OLT01_105P_FQVRNC, 5 (OLT01_105P_FQVRNC-5) | L109: OLT01_105P_FQVRNC, 6 (OLT01_105P_FQVRNC-6) | M109: OLT01_105P_FQVRNC, 7 (OLT01_105P_FQVRNC-7) | N109: OLT01_105P_FQVRNC, 8 (OLT01_105P_FQVRNC-8)
A110: 106 | D110: 106 | E110: F 7800 ST ANNES WAY | F110: OLT01_106P_FQVRNC | G110: OLT01_106P_FQVRNC, 1 (OLT01_106P_FQVRNC-1) | H110: OLT01_106P_FQVRNC, 2 (OLT01_106P_FQVRNC-2) | I110: OLT01_106P_FQVRNC, 3 (OLT01_106P_FQVRNC-3) | J110: OLT01_106P_FQVRNC, 4 (OLT01_106P_FQVRNC-4) | K110: OLT01_106P_FQVRNC, 5 (OLT01_106P_FQVRNC-5) | L110: OLT01_106P_FQVRNC, 6 (OLT01_106P_FQVRNC-6) | M110: OLT01_106P_FQVRNC, 7 (OLT01_106P_FQVRNC-7) | N110: OLT01_106P_FQVRNC, 8 (OLT01_106P_FQVRNC-8)
A111: 107 | D111: 107 | E111: F 6620 OLD MILLS RD | F111: OLT01_107P_FQVRNC | G111: SPARE | H111: OLT01_107P_FQVRNC, 2 (OLT01_107P_FQVRNC-2) | I111: OLT01_107P_FQVRNC, 3 (OLT01_107P_FQVRNC-3) | J111: OLT01_107P_FQVRNC, 4 (OLT01_107P_FQVRNC-4) | K111: OLT01_107P_FQVRNC, 5 (OLT01_107P_FQVRNC-5) | L111: OLT01_107P_FQVRNC, 6 (OLT01_107P_FQVRNC-6) | M111: OLT01_107P_FQVRNC, 7 (OLT01_107P_FQVRNC-7) | N111: OLT01_107P_FQVRNC, 8 (OLT01_107P_FQVRNC-8)
A112: 108 | D112: 108 | E112: F 2329 FAIRWAY VIEW DR | F112: OLT01_108P_FQVRNC | G112: SPARE | H112: SPARE | I112: SPARE | J112: SPARE | K112: SPARE | L112: SPARE | M112: SPARE | N112: OLT01_108P_FQVRNC, 8 (OLT01_108P_FQVRNC-8)
A113: 109 | D113: 109 | E113: F 2329 FAIRWAY VIEW DR | F113: OLT01_109P_FQVRNC | G113: OLT01_109P_FQVRNC, 1 (OLT01_109P_FQVRNC-1) | H113: OLT01_109P_FQVRNC, 2 (OLT01_109P_FQVRNC-2) | I113: OLT01_109P_FQVRNC, 3 (OLT01_109P_FQVRNC-3) | J113: OLT01_109P_FQVRNC, 4 (OLT01_109P_FQVRNC-4) | K113: OLT01_109P_FQVRNC, 5 (OLT01_109P_FQVRNC-5) | L113: OLT01_109P_FQVRNC, 6 (OLT01_109P_FQVRNC-6) | M113: OLT01_109P_FQVRNC, 7 (OLT01_109P_FQVRNC-7) | N113: OLT01_109P_FQVRNC, 8 (OLT01_109P_FQVRNC-8)
A114: 110 | D114: 110 | E114: F 3501 BENTWOOD BLUFFS LN | F114: OLT01_110P_FQVRNC | G114: SPARE | H114: OLT01_110P_FQVRNC, 2 (OLT01_110P_FQVRNC-2) | I114: OLT01_110P_FQVRNC, 3 (OLT01_110P_FQVRNC-3) | J114: OLT01_110P_FQVRNC, 4 (OLT01_110P_FQVRNC-4) | K114: OLT01_110P_FQVRNC, 5 (OLT01_110P_FQVRNC-5) | L114: OLT01_110P_FQVRNC, 6 (OLT01_110P_FQVRNC-6) | M114: OLT01_110P_FQVRNC, 7 (OLT01_110P_FQVRNC-7) | N114: OLT01_110P_FQVRNC, 8 (OLT01_110P_FQVRNC-8)
A115: 111 | D115: 111 | E115: F 3425 FAIRWAY VIEW | F115: OLT01_111P_FQVRNC | G115: SPARE | H115: SPARE | I115: SPARE | J115: SPARE | K115: OLT01_111P_FQVRNC, 5 (OLT01_111P_FQVRNC-5) | L115: OLT01_111P_FQVRNC, 6 (OLT01_111P_FQVRNC-6) | M115: OLT01_111P_FQVRNC, 7 (OLT01_111P_FQVRNC-7) | N115: OLT01_111P_FQVRNC, 8 (OLT01_111P_FQVRNC-8)
A116: 112 | D116: 112 | E116: F 3425 FAIRWAY VIEW | F116: OLT01_112P_FQVRNC | G116: OLT01_112P_FQVRNC, 1 (OLT01_112P_FQVRNC-1) | H116: OLT01_112P_FQVRNC, 2 (OLT01_112P_FQVRNC-2) | I116: OLT01_112P_FQVRNC, 3 (OLT01_112P_FQVRNC-3) | J116: OLT01_112P_FQVRNC, 4 (OLT01_112P_FQVRNC-4) | K116: OLT01_112P_FQVRNC, 5 (OLT01_112P_FQVRNC-5) | L116: OLT01_112P_FQVRNC, 6 (OLT01_112P_FQVRNC-6) | M116: OLT01_112P_FQVRNC, 7 (OLT01_112P_FQVRNC-7) | N116: OLT01_112P_FQVRNC, 8 (OLT01_112P_FQVRNC-8)
...

Sheet SPLICING 1X8 TO 1X4 SPLITS
A1: 1X8 SPLITTER PLACEMENT
A2: =IF(COUNTA(D5:D12)>1,IFERROR(VLOOKUP("*"&D5&"*",CHOOSE({1,2},'CABLE TO 1X8 SPLICING'!$G$5:$G$1000,'CABLE TO 1X8 SPLICING'!$A$5:$A$1000),2,0),VLOOKUP("*"&D12&"*",CHOOSE({1,2},'CABLE TO 1X8 SPLICING'!$N$5:$N$1000,'CABLE TO 1X8 SPLICING'!$A$5:$A$1000),2,0)),"") | C2: =A2
A3: SPLITTER NAME | B3: T COUNT | C3: 1X4 PLACEMENT ADDRESS | D3: SPLIT | E3: SERVICING | F3: SERVICING | G3: SERVICING | H3: SERVICING
A14: 1X8 SPLITTER PLACEMENT
A15: =IF(COUNTA(D18:D25)>1,IFERROR(VLOOKUP("*"&D18&"*",CHOOSE({1,2},'CABLE TO 1X8 SPLICING'!$G$5:$G$1000,'CABLE TO 1X8 SPLICING'!$A$5:$A$1000),2,0),VLOOKUP("*"&D25&"*",CHOOSE({1,2},'CABLE TO 1X8 SPLICING'!$N$5:$N$1000,'CABLE TO 1X8 SPLICING'!$A$5:$A$1000),2,0)),"") | C15: =A15
A16: SPLITTER NAME | B16: T COUNT | C16: 1X4 PLACEMENT ADDRESS | D16: SPLIT | E16: SERVICING | F16: SERVICING | G16: SERVICING | H16: SERVICING
A27: 1X8 SPLITTER PLACEMENT
A28: =IF(COUNTA(D31:D38)>1,IFERROR(VLOOKUP("*"&D31&"*",CHOOSE({1,2},'CABLE TO 1X8 SPLICING'!$G$5:$G$1000,'CABLE TO 1X8 SPLICING'!$A$5:$A$1000),2,0),VLOOKUP("*"&D38&"*",CHOOSE({1,2},'CABLE TO 1X8 SPLICING'!$N$5:$N$1000,'CABLE TO 1X8 SPLICING'!$A$5:$A$1000),2,0)),"") | C28: =A28
A29: SPLITTER NAME | B29: T COUNT | C29: 1X4 PLACEMENT ADDRESS | D29: SPLIT | E29: SERVICING | F29: SERVICING | G29: SERVICING | H29: SERVICING
A40: 1X8 SPLITTER PLACEMENT
A41: =IF(COUNTA(D44:D51)>1,IFERROR(VLOOKUP("*"&D44&"*",CHOOSE({1,2},'CABLE TO 1X8 SPLICING'!$G$5:$G$1000,'CABLE TO 1X8 SPLICING'!$A$5:$A$1000),2,0),VLOOKUP("*"&D51&"*",CHOOSE({1,2},'CABLE TO 1X8 SPLICING'!$N$5:$N$1000,'CABLE TO 1X8 SPLICING'!$A$5:$A$1000),2,0)),"") | C41: =A41
A42: SPLITTER NAME | B42: T COUNT | C42: 1X4 PLACEMENT ADDRESS | D42: SPLIT | E42: SERVICING | F42: SERVICING | G42: SERVICING | H42: SERVICING
A53: 1X8 SPLITTER PLACEMENT
A54: =IF(COUNTA(D57:D64)>1,IFERROR(VLOOKUP("*"&D57&"*",CHOOSE({1,2},'CABLE TO 1X8 SPLICING'!$G$5:$G$1000,'CABLE TO 1X8 SPLICING'!$A$5:$A$1000),2,0),VLOOKUP("*"&D64&"*",CHOOSE({1,2},'CABLE TO 1X8 SPLICING'!$N$5:$N$1000,'CABLE TO 1X8 SPLICING'!$A$5:$A$1000),2,0)),"") | C54: =A54
A55: SPLITTER NAME | B55: T COUNT | C55: 1X4 PLACEMENT ADDRESS | D55: SPLIT | E55: SERVICING | F55: SERVICING | G55: SERVICING | H55: SERVICING
A66: 1X8 SPLITTER PLACEMENT
A67: =IF(COUNTA(D70:D77)>1,IFERROR(VLOOKUP("*"&D70&"*",CHOOSE({1,2},'CABLE TO 1X8 SPLICING'!$G$5:$G$1000,'CABLE TO 1X8 SPLICING'!$A$5:$A$1000),2,0),VLOOKUP("*"&D77&"*",CHOOSE({1,2},'CABLE TO 1X8 SPLICING'!$N$5:$N$1000,'CABLE TO 1X8 SPLICING'!$A$5:$A$1000),2,0)),"") | C67: =A67
A68: SPLITTER NAME | B68: T COUNT | C68: 1X4 PLACEMENT ADDRESS | D68: SPLIT | E68: SERVICING | F68: SERVICING | G68: SERVICING | H68: SERVICING
A79: =IF(COUNTA(D82:D89)>1,IFERROR(VLOOKUP("*"&D82&"*",CHOOSE({1,2},'CABLE TO 1X8 SPLICING'!$G$5:$G$1000,'CABLE TO 1X8 SPLICING'!$A$5:$A$1000),2,0),VLOOKUP("*"&D89&"*",CHOOSE({1,2},'CABLE TO 1X8 SPLICING'!$N$5:$N$1000,'CABLE TO 1X8 SPLICING'!$A$5:$A$1000),2,0)),"") | C79: =A79
A80: SPLITTER NAME | B80: T COUNT | C80: 1X4 PLACEMENT ADDRESS | D80: SPLIT | E80: SERVICING | F80: SERVICING | G80: SERVICING | H80: SERVICING
A91: =IF(COUNTA(D94:D101)>1,IFERROR(VLOOKUP("*"&D94&"*",CHOOSE({1,2},'CABLE TO 1X8 SPLICING'!$G$5:$G$1000,'CABLE TO 1X8 SPLICING'!$A$5:$A$1000),2,0),VLOOKUP("*"&D101&"*",CHOOSE({1,2},'CABLE TO 1X8 SPLICING'!$N$5:$N$1000,'CABLE TO 1X8 SPLICING'!$A$5:$A$1000),2,0)),"") | C91: =A91
A92: SPLITTER NAME | B92: T COUNT | C92: 1X4 PLACEMENT ADDRESS | D92: SPLIT | E92: SERVICING | F92: SERVICING | G92: SERVICING | H92: SERVICING
A103: =IF(COUNTA(D106:D113)>1,IFERROR(VLOOKUP("*"&D106&"*",CHOOSE({1,2},'CABLE TO 1X8 SPLICING'!$G$5:$G$1000,'CABLE TO 1X8 SPLICING'!$A$5:$A$1000),2,0),VLOOKUP("*"&D113&"*",CHOOSE({1,2},'CABLE TO 1X8 SPLICING'!$N$5:$N$1000,'CABLE TO 1X8 SPLICING'!$A$5:$A$1000),2,0)),"") | C103: =A103
A104: SPLITTER NAME | B104: T COUNT | C104: 1X4 PLACEMENT ADDRESS | D104: SPLIT | E104: SERVICING | F104: SERVICING | G104: SERVICING | H104: SERVICING
A115: =IF(COUNTA(D118:D125)>1,IFERROR(VLOOKUP("*"&D118&"*",CHOOSE({1,2},'CABLE TO 1X8 SPLICING'!$G$5:$G$1000,'CABLE TO 1X8 SPLICING'!$A$5:$A$1000),2,0),VLOOKUP("*"&D125&"*",CHOOSE({1,2},'CABLE TO 1X8 SPLICING'!$N$5:$N$1000,'CABLE TO 1X8 SPLICING'!$A$5:$A$1000),2,0)),"") | C115: =A115
A116: SPLITTER NAME | B116: T COUNT | C116: 1X4 PLACEMENT ADDRESS | D116: SPLIT | E116: SERVICING | F116: SERVICING | G116: SERVICING | H116: SERVICING
A127: =IF(COUNTA(D130:D137)>1,IFERROR(VLOOKUP("*"&D130&"*",CHOOSE({1,2},'CABLE TO 1X8 SPLICING'!$G$5:$G$1000,'CABLE TO 1X8 SPLICING'!$A$5:$A$1000),2,0),VLOOKUP("*"&D137&"*",CHOOSE({1,2},'CABLE TO 1X8 SPLICING'!$N$5:$N$1000,'CABLE TO 1X8 SPLICING'!$A$5:$A$1000),2,0)),"") | C127: =A127
A128: SPLITTER NAME | B128: T COUNT | C128: 1X4 PLACEMENT ADDRESS | D128: SPLIT | E128: SERVICING | F128: SERVICING | G128: SERVICING | H128: SERVICING
C139: =A139

Sheet FINAL ADDRESS LIST
A1: ADDRESS | B1: UNIT | C1: City | D1: STATE | E1: ZIP | F1: BUSINESS/RESIDENTIAL | G1: House Type | H1: Servicablity
A2: ='House Count'!A2 | B2: ='House Count'!E2 | C2: ='House Count'!B2 | D2: ='House Count'!C2 | E2: ='House Count'!D2 | F2: =IF(G2="RES-SFU","RESIDENTIAL",IF(G2="RES-HOA","RESIDENTIAL",IF(G2="RES-MDU","RESIDENTIAL",IF(G2="COMM-SU","BUSINESS",IF(G2="COM-MTU","BUSINESS",IF(G2="ENT","BUSINESS","")))))) | G2: ='House Count'!F2 | H2: ='House Count'!H2
A3: ='House Count'!A3 | B3: ='House Count'!E3 | C3: ='House Count'!B3 | D3: ='House Count'!C3 | E3: ='House Count'!D3 | F3: =IF(G3="RES-SFU","RESIDENTIAL",IF(G3="RES-HOA","RESIDENTIAL",IF(G3="RES-MDU","RESIDENTIAL",IF(G3="COMM-SU","BUSINESS",IF(G3="COM-MTU","BUSINESS",IF(G3="ENT","BUSINESS","")))))) | G3: ='House Count'!F3 | H3: ='House Count'!H3
A4: ='House Count'!A4 | B4: ='House Count'!E4 | C4: ='House Count'!B4 | D4: ='House Count'!C4 | E4: ='House Count'!D4 | F4: =IF(G4="RES-SFU","RESIDENTIAL",IF(G4="RES-HOA","RESIDENTIAL",IF(G4="RES-MDU","RESIDENTIAL",IF(G4="COMM-SU","BUSINESS",IF(G4="COM-MTU","BUSINESS",IF(G4="ENT","BUSINESS","")))))) | G4: ='House Count'!F4 | H4: ='House Count'!H4
A5: ='House Count'!A5 | B5: ='House Count'!E5 | C5: ='House Count'!B5 | D5: ='House Count'!C5 | E5: ='House Count'!D5 | F5: =IF(G5="RES-SFU","RESIDENTIAL",IF(G5="RES-HOA","RESIDENTIAL",IF(G5="RES-MDU","RESIDENTIAL",IF(G5="COMM-SU","BUSINESS",IF(G5="COM-MTU","BUSINESS",IF(G5="ENT","BUSINESS","")))))) | G5: ='House Count'!F5 | H5: ='House Count'!H5
A6: ='House Count'!A6 | B6: ='House Count'!E6 | C6: ='House Count'!B6 | D6: ='House Count'!C6 | E6: ='House Count'!D6 | F6: =IF(G6="RES-SFU","RESIDENTIAL",IF(G6="RES-HOA","RESIDENTIAL",IF(G6="RES-MDU","RESIDENTIAL",IF(G6="COMM-SU","BUSINESS",IF(G6="COM-MTU","BUSINESS",IF(G6="ENT","BUSINESS","")))))) | G6: ='House Count'!F6 | H6: ='House Count'!H6
A7: ='House Count'!A7 | B7: ='House Count'!E7 | C7: ='House Count'!B7 | D7: ='House Count'!C7 | E7: ='House Count'!D7 | F7: =IF(G7="RES-SFU","RESIDENTIAL",IF(G7="RES-HOA","RESIDENTIAL",IF(G7="RES-MDU","RESIDENTIAL",IF(G7="COMM-SU","BUSINESS",IF(G7="COM-MTU","BUSINESS",IF(G7="ENT","BUSINESS","")))))) | G7: ='House Count'!F7 | H7: ='House Count'!H7
A8: ='House Count'!A8 | B8: ='House Count'!E8 | C8: ='House Count'!B8 | D8: ='House Count'!C8 | E8: ='House Count'!D8 | F8: =IF(G8="RES-SFU","RESIDENTIAL",IF(G8="RES-HOA","RESIDENTIAL",IF(G8="RES-MDU","RESIDENTIAL",IF(G8="COMM-SU","BUSINESS",IF(G8="COM-MTU","BUSINESS",IF(G8="ENT","BUSINESS","")))))) | G8: ='House Count'!F8 | H8: ='House Count'!H8
A9: ='House Count'!A9 | B9: ='House Count'!E9 | C9: ='House Count'!B9 | D9: ='House Count'!C9 | E9: ='House Count'!D9 | F9: =IF(G9="RES-SFU","RESIDENTIAL",IF(G9="RES-HOA","RESIDENTIAL",IF(G9="RES-MDU","RESIDENTIAL",IF(G9="COMM-SU","BUSINESS",IF(G9="COM-MTU","BUSINESS",IF(G9="ENT","BUSINESS","")))))) | G9: ='House Count'!F9 | H9: ='House Count'!H9
A10: ='House Count'!A10 | B10: ='House Count'!E10 | C10: ='House Count'!B10 | D10: ='House Count'!C10 | E10: ='House Count'!D10 | F10: =IF(G10="RES-SFU","RESIDENTIAL",IF(G10="RES-HOA","RESIDENTIAL",IF(G10="RES-MDU","RESIDENTIAL",IF(G10="COMM-SU","BUSINESS",IF(G10="COM-MTU","BUSINESS",IF(G10="ENT","BUSINESS","")))))) | G10: ='House Count'!F10 | H10: ='House Count'!H10
A11: ='House Count'!A11 | B11: ='House Count'!E11 | C11: ='House Count'!B11 | D11: ='House Count'!C11 | E11: ='House Count'!D11 | F11: =IF(G11="RES-SFU","RESIDENTIAL",IF(G11="RES-HOA","RESIDENTIAL",IF(G11="RES-MDU","RESIDENTIAL",IF(G11="COMM-SU","BUSINESS",IF(G11="COM-MTU","BUSINESS",IF(G11="ENT","BUSINESS","")))))) | G11: ='House Count'!F11 | H11: ='House Count'!H11
A12: ='House Count'!A12 | B12: ='House Count'!E12 | C12: ='House Count'!B12 | D12: ='House Count'!C12 | E12: ='House Count'!D12 | F12: =IF(G12="RES-SFU","RESIDENTIAL",IF(G12="RES-HOA","RESIDENTIAL",IF(G12="RES-MDU","RESIDENTIAL",IF(G12="COMM-SU","BUSINESS",IF(G12="COM-MTU","BUSINESS",IF(G12="ENT","BUSINESS","")))))) | G12: ='House Count'!F12 | H12: ='House Count'!H12
A13: ='House Count'!A13 | B13: ='House Count'!E13 | C13: ='House Count'!B13 | D13: ='House Count'!C13 | E13: ='House Count'!D13 | F13: =IF(G13="RES-SFU","RESIDENTIAL",IF(G13="RES-HOA","RESIDENTIAL",IF(G13="RES-MDU","RESIDENTIAL",IF(G13="COMM-SU","BUSINESS",IF(G13="COM-MTU","BUSINESS",IF(G13="ENT","BUSINESS","")))))) | G13: ='House Count'!F13 | H13: ='House Count'!H13
... A1500: ='House Count'!A1500 | B1500: ='House Count'!E1500 | C1500: ='House Count'!B1500 | D1500: ='House Count'!C1500 | E1500: ='House Count'!D1500 | F1500: =IF(G1500="RES-SFU","RESIDENTIAL",IF(G1500="RES-HOA","RESIDENTIAL",IF(G1500="RES-MDU","RESIDENTIAL",IF(G1500="COMM-SU","BUSINESS",IF(G1500="COM-MTU","BUSINESS",IF(G1500="ENT","BUSINESS","")))))) | G1500: ='House Count'!F1500 | H1500: ='House Count'!H1500

Sheet PERMITS
A1: PERMITS WORKSHEET
A3: DOT | J3: MUNICIPAL
A4: NAME | C4: DESCRIPTION | G4: AMOUNT | J4: NAME | L4: DESCRIPTION | P4: AMOUNT
G5: 0 | L5: CITY | P5: 500
L6: COUNTY | P6: 500
A20: RR | J20: EASEMENTS
A21: NAME | C21: DESCRIPTION | G21: AMOUNT | J21: NAME | L21: DESCRIPTION | P21: AMOUNT
G22: 0
A37: POLE | J37: THIRD-PARTY SPLICING
A38: NAME | C38: DESCRIPTION | G38: AMOUNT | J38: Number | L38: DESCRIPTION | P38: AMOUNT
G39: 0
A54: OTHER | J54: CELL SITE
A55: NAME | C55: DESCRIPTION | G55: AMOUNT | J55: NAME | L55: DESCRIPTION | P55: AMOUNT
C56: CONTINGENT LABOR | G56: 10000
A70: 0 | C70: MISC Access Equipment and install charge | G70: =A70*1350
A72: TRAFFIC CONTROL
A73: NAME | C73: DESCRIPTION | L73: Price | N73: Unit | O73: Quantity | P73: AMOUNT
A74: Standard Flagging Operation | C74: Includes up to 2 crew members, 1 AWP work truck with rotating lights, 8 advanced warning signs, 40 cones and up to 8 hours on site with mobilization. | L74: 578.2 | N74: Daily | P74: =SUM(O74*L74)
A76: Standard Lane Closure- No TMA | C76: Includes up to 2 crew members, 1 AWP work truck with rotating lights, 1 arrow board, 10 advanced warning signs, 70 cones and up to 8 hours on site with mobilization. | L76: 676.2 | N76: Daily | P76: =SUM(O76*L76)
A78: Standard Shoulder Closure - No TMA | C78: Includes up to 2 crew members, 1 AWP work truck with rotating lights, 6 advanced warning signs, 40 cones and up to 8 hours on site with mobilization. | L78: 578.2 | N78: Daily | P78: =SUM(O78*L78)
A80: TMA | C80: Truck Mounted Attenuator (TMA)/Crash Truck,(Driver is extra, see below for hourly rate) | L80: 350 | N80: Daily | P80: =SUM(O80*L80)
